<?xml version="1.0" ?>
<robot name="newbot" xmlns:xacro="http://ros.org/wiki/xacro">
  <xacro:include filename="$(find newbot_description)/urdf/common_properties.xacro"/>
  <xacro:include filename="$(find newbot_description)/urdf/newbot.gazebo.xacro"/>

  <link name="base_footprint"/>

  <joint name="base_joint" type="fixed">
    <parent link="base_footprint"/>
    <child link="base_link"/>
    <origin xyz="0.0 0.0 0.010" rpy="0 0 0"/>
  </joint>

  <link name="base_link">
    <visual>
      <origin xyz="-0.06 0 0.025" rpy="0 0 0"/>
       <geometry>
        <box size="0.2 0.135 0.035"/>
      </geometry>
      <material name="light_black"/>
    </visual>

    <collision>
      <origin xyz="-0.06 0 0.025" rpy="0 0 0"/>
       <geometry>
        <box size="0.2 0.135 0.035"/>
      </geometry>
    </collision>

    <visual>
      <origin xyz="0.005 0 0.05" rpy=" 0 0 0"/>
      <geometry>
        <box size="0.07 0.09 0.015"/>
      </geometry>
      <material name="light_black"/>
    </visual>

    <collision>
      <origin xyz="0.005 0 0.05" rpy=" 0 0 0"/>
      <geometry>
        <box size="0.07 0.09 0.015"/>
      </geometry>
    </collision>

    <inertial>
      <origin xyz="0 0 0" rpy="0 0 0"/>
      <mass value="8.2573504e-01"/>
      <inertia ixx="2.2124416e-03" ixy="-1.2294101e-05" ixz="3.4938785e-05"
               iyy="2.1193702e-03" iyz="-5.0120904e-06"
               izz="2.0064271e-03" />
    </inertial>
  </link>

  <joint name="wheel_left_joint" type="continuous">
    <parent link="base_link"/>
    <child link="wheel_left_link"/>
    <origin xyz="0.0 0.08 0.023" rpy="-1.57 0 0"/>
    <axis xyz="0 0 1"/>
  </joint>

  <link name="wheel_left_link">
    <visual>
      <origin xyz="0 0 0" rpy="0 0 0"/>
      <geometry>
        <cylinder length="0.018" radius="0.033"/>
      </geometry>
      <material name="dark"/>
    </visual>

    <collision>
      <origin xyz="0 0 0" rpy="0 0 0"/>
      <geometry>
        <cylinder length="0.018" radius="0.033"/>
      </geometry>
    </collision>

    <inertial>
      <origin xyz="0 0 0" />
      <mass value="2.8498940e-02" />
      <inertia ixx="1.1175580e-05" ixy="-4.2369783e-11" ixz="-5.9381719e-09"
               iyy="1.1192413e-05" iyz="-1.4400107e-11"
               izz="2.0712558e-05" />
      </inertial>
  </link>

  <joint name="wheel_right_joint" type="continuous">
    <parent link="base_link"/>
    <child link="wheel_right_link"/>
    <origin xyz="0.0 -0.080 0.023" rpy="-1.57 0 0"/>
    <axis xyz="0 0 1"/>
  </joint>

  <link name="wheel_right_link">
    <visual>
      <origin xyz="0 0 0" rpy="0 0 0"/>
      <geometry>
        <cylinder length="0.018" radius="0.033"/>
      </geometry>
      <material name="dark"/>
    </visual>

    <collision>
      <origin xyz="0 0 0" rpy="0 0 0"/>
      <geometry>
        <cylinder length="0.018" radius="0.033"/>
      </geometry>
    </collision>

    <inertial>
      <origin xyz="0 0 0" />
      <mass value="2.8498940e-02" />
      <inertia ixx="1.1175580e-05" ixy="-4.2369783e-11" ixz="-5.9381719e-09"
               iyy="1.1192413e-05" iyz="-1.4400107e-11"
               izz="2.0712558e-05" />
      </inertial>
  </link>

  <joint name="caster_back_joint" type="fixed">
    <parent link="base_link"/>
    <child link="caster_back_link"/>
    <origin xyz="0 0 0" rpy="0 0 0"/>
  </joint>

  <link name="caster_back_link">
    <visual>
      <origin xyz="-0.13 0 0.005" rpy="0 0 0"/>
      <geometry>
        <sphere radius="0.015"/>
      </geometry>
    </visual>

    <collision>
      <origin xyz="-0.13 0 0.005" rpy="0 0 0"/>
      <geometry>
        <sphere radius="0.015"/>
      </geometry>
      <surface>
        <friction>
          <ode>
            <mu>0</mu>
            <mu2>0</mu2>
            <slip1>1.0</slip1>
            <slip2>1.0</slip2>
          </ode>
        </friction>
      </surface>
    </collision>

    <inertial>
      <origin xyz="0 0 0" />
      <mass value="0.005" />
      <inertia ixx="0.001" ixy="0.0" ixz="0.0"
               iyy="0.001" iyz="0.0"
               izz="0.001" />
    </inertial>
  </link>

  <joint name="imu_joint" type="fixed">
    <parent link="base_link"/>
    <child link="imu_link"/>
    <origin xyz="-0.032 0 0.068" rpy="0 0 0"/>
  </joint>

  <link name="imu_link"/>

  <joint name="scan_joint" type="fixed">
    <parent link="base_link"/>
    <child link="base_scan"/>
    <origin xyz="0.005 0 0.09" rpy="0 0 0"/>
  </joint>

  <!--link name="base_scan">
    <visual>
      <origin xyz="0.03 0 0.06" rpy="0 0 0"/>
      <geometry>
        <cylinder length="0.005" radius="0.01"/>
      </geometry>
      <material name="dark"/>
    </visual>

    <collision>
      <origin xyz="0.03 0 0.06" rpy="0 0 0"/>
      <geometry>
        <cylinder length="0.005" radius="0.01"/>
      </geometry>
    </collision>

    <inertial>
      <mass value="0.114" />
      <origin xyz="0 0 0" />
      <inertia ixx="0.001" ixy="0.0" ixz="0.0"
               iyy="0.001" iyz="0.0"
               izz="0.001" />
    </inertial>
  </link-->

  <link name="base_scan">
    <collision>
      <origin xyz="0 0 0" rpy="0 0 1.57"/>
      <geometry>
    	<box size="0.1 0.1 0.1"/>
      </geometry>
    </collision>

    <visual>
      <origin xyz="0 0 0" rpy="0 0 1.57"/>
      <geometry>
        <mesh filename="package://newbot_description/meshes/kinect.dae"/>
      </geometry>
    </visual>

    <inertial>
      <mass value="1e-5" />
      <origin xyz="0 0 0" rpy="0 0 0"/>
      <inertia ixx="1e-6" ixy="0" ixz="0" iyy="1e-6" iyz="0" izz="1e-6" />
    </inertial>
  </link>

</robot>
